"""created a many to many  model relationship trail and error

Revision ID: ad099ca64e3c
Revises: 72b6155f3d7c
Create Date: 2025-05-14 20:20:47.907052

"""
from alembic import op
import sqlalchemy as sa


# revision identifiers, used by Alembic.
revision = 'ad099ca64e3c'
down_revision = '72b6155f3d7c'
branch_labels = None
depends_on = None


def upgrade():
    # ### commands auto generated by Alembic - please adjust! ###
    op.create_table('machines',
    sa.Column('id', sa.Integer(), nullable=False),
    sa.Column('type', sa.String(), nullable=False),
    sa.Column('serial_number', sa.String(), nullable=False),
    sa.Column('status', sa.String(), nullable=True),
    sa.Column('created_at', sa.DateTime(), nullable=False),
    sa.Column('updated_at', sa.DateTime(), nullable=False),
    sa.Column('soldier_id', sa.Integer(), nullable=False),
    sa.ForeignKeyConstraint(['soldier_id'], ['soldiers.id'], name=op.f('fk_machines_soldier_id_soldiers')),
    sa.PrimaryKeyConstraint('id'),
    sa.UniqueConstraint('serial_number')
    )
    # ### end Alembic commands ###


def downgrade():
    # ### commands auto generated by Alembic - please adjust! ###
    op.drop_table('machines')
    # ### end Alembic commands ###
